<?xml version="1.0" ?>
<!-- PuzzleBot differential drive -->
<robot name="puzzlebot" xmlns:xacro="http://www.ros.org/wiki/xacro">

<!-- files for gazebo costumization -->
<xacro:include filename="$(find puzzlebot_gazebo)/urdf/materials.xacro" />
<xacro:include filename="$(find puzzlebot_gazebo)/urdf/parameters.xacro" />
<xacro:include filename="$(find puzzlebot_gazebo)/urdf/puzzlebot.gazebo" />
<xacro:property name="PI" value="3.1415926535897931"/>
<xacro:property name="chassisX" value="0.2"/>
<xacro:property name="chassisY" value="0.16"/>
<xacro:property name="chassisZ" value="0.06"/>
<xacro:property name="chassisMass" value="0.710"/>

<xacro:property name="casterRadius" value="0.0065"/>
<xacro:property name="casterMass" value="0.012"/>

<xacro:property name="wheelHeight" value="0.01"/>
<xacro:property name="wheelRadius" value="0.05"/>
<xacro:property name="wheelPos" value="0.05"/>
<xacro:property name="wheelDistance" value="0.08"/>
<xacro:property name="wheelMass" value="0.03"/>

<xacro:property name="cameraSize" value="0.07"/>
<xacro:property name="cameraMass" value="0.018"/>
<xacro:property name="cameraX" value="0.02"/>
<xacro:property name="cameraY" value="0.04"/>
<xacro:property name="cameraZ" value="0.06"/>
<!-- Dummy link to fiz robot chassis -->
  <link name="base_link">
    <pose>0 0 0 0 0 0</pose>
  </link>
  
  <joint name="base_link_to_chassis" type="fixed">
	   <parent link="base_link"/>
	   <child link="chassis"/>
  </joint>

  <link name="chassis">
    <pose>0 0 0 0 0 0</pose>
    <visual>
      <origin xyz="0 0 0" rpy="${PI/2} 0 ${PI/2}"/>
          <geometry>
          	 <mesh filename="file://${mesh_chassis}"/>
          </geometry> 
    </visual>

    <collision name="collision_chassis">
    	<origin rpy="0 0 0" xyz="0 0 0"/>
          <geometry>
            	 <box size="${chassisX} ${chassisY} ${chassisZ}"/> 
          </geometry>
    </collision>


   <!-- agregar caster wheel en frame --> 
    <collision>
	    <origin xyz="-0.095 0 -0.0425" rpy="0 0 0"/>
		  <geometry>
		     <sphere radius="${casterRadius}"/>
		  </geometry>
		        <surface>
	      <friction>
	         <ode>
	          <slip1>0.0</slip1>
	          <slip2>0.0</slip2>
	         </ode>
	      </friction>
      </surface>
	  </collision>

	  <visual>
      <origin xyz="-0.095 0 -0.0425" rpy="0 0 0"/>
          <geometry>
          	   <sphere radius="${casterRadius}"/>
          </geometry>
    </visual>
 
  </link>

 <!--RIGHT WHEEL -->
	<link name="right_wheel">
	  <visual>
	  	<origin xyz="0 0 0" rpy="-${PI/2} 0 0" />
	    <geometry>
	      <!-- with mesh-->
	      	<mesh filename="file://${mesh_wheel}"/>
	    </geometry>
	  </visual>

	  <collision>
		  <origin xyz="0 0 0 " rpy="-${PI/2} 0 0"/>
			  <geometry>
			     <cylinder length="${wheelHeight}" radius="${wheelRadius}" />
			  </geometry>
	  </collision>
	</link>

<!-- LEFT WHEEL -->
	<link name="left_wheel">
	  <visual>
	    <geometry>
        <!-- with mesh-->
	      	<mesh filename="file://${mesh_wheel}"/>
	    	<!-- cylinder only 
	    	<cylinder length="${wheelHeight}" radius="${wheelRadius}"/> -->
	    </geometry>
	    <origin xyz="0 0 0" rpy="${PI/2} 0 0" />
	  </visual>
	  
	  <collision>
		  <origin xyz="0 0 0" rpy="${PI/2} 0 0" />
		  <geometry>
		     <cylinder length="${wheelHeight}" radius="${wheelRadius}"/>
		  </geometry>
	  </collision>
	</link>
	     	  

<!-- JOINTS  --> 
 
  <joint name="base_to_right_w" type="continuous">
	  <parent link="chassis" />
	  <child link="right_wheel" />
	  <origin xyz="0.05 -0.09 0.0" />
		<axis xyz="0 1 0" rpy="0 0 0" />
	<!--	<limit effort="100" velocity="100"/>
		<joint_properties damping="0.0" friction="0.0"/>-->
	</joint>

	<joint name="base_to_left_w" type="continuous">
	  <parent link="chassis" />
	  <child link="left_wheel" />
	  <origin xyz="0.05 0.09 0" />
	  <axis xyz="0 1 0" rpy="0 0 0" />
		<!--<limit effort="100" velocity="100"/>
		<joint_properties damping="0.0" friction="0.0"/>-->
	</joint>
</robot>