<?xml version="1.0"?>

<robot name="puzzlebot" xmlns:xacro="http://www.ros.org/wiki/xacro">

<xacro:include filename="$(find puzzlebot_rviz)/src/urdf/parameters.xacro" />
<xacro:include filename="$(find puzzlebot_rviz)/src/urdf/macros.xacro" />
<xacro:include filename="$(find puzzlebot_rviz)/src/urdf/materials.xacro" />
<xacro:include filename="$(find puzzlebot_rviz)/src/urdf/puzzlebot.gazebo" />

  <!--PUZZLEBOT -->
  <link name="base_link">
    <pose>0 0 0 0 0 0</pose>
    <visual>
          <geometry>
            <mesh filename="file://${mesh_puzzlebot}"/>
          </geometry> 
    </visual>
  </link>

  <joint name="base_link_to_chassis" type="fixed">
	   <parent link="base_link"/>
	   <child link="chassis"/>
  </joint>

  <!--CHASSIS -->
  <link name="chassis">
    <pose>0 0 0 0 0 0</pose>
    <visual>
    <origin xyz="0 0 0" rpy="1.5 0 1.5"/>
          <geometry>
            <mesh filename="file://${mesh_chassis}"/>
          </geometry> 
    </visual>
  
  <collision name="collision_chassis">
    	<origin rpy="0 0 0" xyz="0 0 0"/>
          <geometry>
            	 <box size="0.2 0.16 0.06"/> 
          </geometry>
    </collision>
  
  <!-- Caster wheel en frame --> 
    <collision>
	    <origin xyz="-0.095 0 -0.0425" rpy="0 0 0"/>
		  <geometry>
		     <sphere radius="0.0065"/>
		  </geometry>
		        <surface>
	      <friction>
	         <ode>
	          <slip1>0.0</slip1>
	          <slip2>0.0</slip2>
	         </ode>
	      </friction>
      </surface>
	  </collision>

	  <visual>
      <origin xyz="-0.095 0 -0.0425" rpy="0 0 0"/>
          <geometry>
          	   <sphere radius="0.0065"/>
          </geometry>
    </visual>
 
  </link>

  <!--RIGHT WHEEL -->
	<link name="right_wheel">
	  <visual>
	    <geometry>
	      	<mesh filename="file://${mesh_wheel}"/>
	    </geometry>
      <origin xyz="0 0 0" rpy="-1.5 0 0" />
	  </visual>

    <collision>
		  <origin xyz="0 0 0 " rpy="-1.5 0 0"/>
			  <geometry>
			     <cylinder length="0.01" radius="0.05" />
			  </geometry>
	  </collision>

	</link>

  <!-- LEFT WHEEL -->
	<link name="left_wheel">
	  <visual>
	    <geometry>
        <!-- with mesh-->
	      	<mesh filename="file://${mesh_wheel}"/>
	    </geometry>
      <origin xyz="0 0 0" rpy="1.5 0 0" />
	  </visual>

    <collision>
		  <origin xyz="0 0 0" rpy="1.5 0 0" />
		  <geometry>
		     <cylinder length="0.01" radius="0.05"/>
		  </geometry>
	  </collision>

	</link>

  <!-- JOINTS  --> 

  <joint name="base_to_right_w" type="continuous">
	  <parent link="chassis" />
	  <child link="right_wheel" />
	  <origin xyz="0.05 -0.096 0.0" />
		<axis xyz="0 1 0" rpy="0 0 0" />
	</joint>

	<joint name="base_to_left_w" type="continuous">
	  <parent link="chassis" />
	  <child link="left_wheel" />
	  <origin xyz="0.05 0.096 0" />
	  <axis xyz="0 1 0" rpy="0 0 0" />
	</joint>

<!---->

</robot>